2023-10-27 15:32:34,910 [ERROR] [log] - Internal Server Error: /news/create
Traceback (most recent call last):
  File "C:\Users\Max\PycharmProjects\News_01\venv\Lib\site-packages\django\core\handlers\exception.py", line 55, in inner
    response = get_response(request)
               ^^^^^^^^^^^^^^^^^^^^^
  File "C:\Users\Max\PycharmProjects\News_01\venv\Lib\site-packages\django\core\handlers\base.py", line 197, in _get_response
    response = wrapped_callback(request, *callback_args, **callback_kwargs)
               ^^^^^^^^^^^^^^^^^^^^^^^^^^^^^^^^^^^^^^^^^^^^^^^^^^^^^^^^^^^^
  File "C:\Users\Max\PycharmProjects\News_01\venv\Lib\site-packages\django\views\generic\base.py", line 104, in view
    return self.dispatch(request, *args, **kwargs)
           ^^^^^^^^^^^^^^^^^^^^^^^^^^^^^^^^^^^^^^^
  File "C:\Users\Max\PycharmProjects\News_01\venv\Lib\site-packages\django\contrib\auth\mixins.py", line 109, in dispatch
    return super().dispatch(request, *args, **kwargs)
           ^^^^^^^^^^^^^^^^^^^^^^^^^^^^^^^^^^^^^^^^^^
  File "C:\Users\Max\PycharmProjects\News_01\venv\Lib\site-packages\django\views\generic\base.py", line 143, in dispatch
    return handler(request, *args, **kwargs)
           ^^^^^^^^^^^^^^^^^^^^^^^^^^^^^^^^^
  File "C:\Users\Max\PycharmProjects\News_01\venv\Lib\site-packages\django\views\generic\edit.py", line 184, in post
    return super().post(request, *args, **kwargs)
           ^^^^^^^^^^^^^^^^^^^^^^^^^^^^^^^^^^^^^^
  File "C:\Users\Max\PycharmProjects\News_01\venv\Lib\site-packages\django\views\generic\edit.py", line 153, in post
    return self.form_valid(form)
           ^^^^^^^^^^^^^^^^^^^^^
  File "C:\Users\Max\PycharmProjects\News_01\project\news_article\views.py", line 156, in form_valid
    return super().form_valid(form)
           ^^^^^^^^^^^^^^^^^^^^^^^^
  File "C:\Users\Max\PycharmProjects\News_01\venv\Lib\site-packages\django\views\generic\edit.py", line 135, in form_valid
    self.object = form.save()
                  ^^^^^^^^^^^
  File "C:\Users\Max\PycharmProjects\News_01\venv\Lib\site-packages\django\forms\models.py", line 542, in save
    self.instance.save()
  File "C:\Users\Max\PycharmProjects\News_01\project\news_article\models.py", line 74, in save
    raise ValidationError("Пользователь уже опубликовал максимальное количество записей за сутки.")
django.core.exceptions.ValidationError: ['Пользователь уже опубликовал максимальное количество записей за сутки.']
2023-10-27 15:32:34,920 [ERROR] [basehttp] - "POST /news/create HTTP/1.1" 500 145
2023-10-27 15:32:55,949 [ERROR] [log] - Internal Server Error: /news/create
Traceback (most recent call last):
  File "C:\Users\Max\PycharmProjects\News_01\venv\Lib\site-packages\django\core\handlers\exception.py", line 55, in inner
    response = get_response(request)
               ^^^^^^^^^^^^^^^^^^^^^
  File "C:\Users\Max\PycharmProjects\News_01\venv\Lib\site-packages\django\core\handlers\base.py", line 197, in _get_response
    response = wrapped_callback(request, *callback_args, **callback_kwargs)
               ^^^^^^^^^^^^^^^^^^^^^^^^^^^^^^^^^^^^^^^^^^^^^^^^^^^^^^^^^^^^
  File "C:\Users\Max\PycharmProjects\News_01\venv\Lib\site-packages\django\views\generic\base.py", line 104, in view
    return self.dispatch(request, *args, **kwargs)
           ^^^^^^^^^^^^^^^^^^^^^^^^^^^^^^^^^^^^^^^
  File "C:\Users\Max\PycharmProjects\News_01\venv\Lib\site-packages\django\contrib\auth\mixins.py", line 109, in dispatch
    return super().dispatch(request, *args, **kwargs)
           ^^^^^^^^^^^^^^^^^^^^^^^^^^^^^^^^^^^^^^^^^^
  File "C:\Users\Max\PycharmProjects\News_01\venv\Lib\site-packages\django\views\generic\base.py", line 143, in dispatch
    return handler(request, *args, **kwargs)
           ^^^^^^^^^^^^^^^^^^^^^^^^^^^^^^^^^
  File "C:\Users\Max\PycharmProjects\News_01\venv\Lib\site-packages\django\views\generic\edit.py", line 184, in post
    return super().post(request, *args, **kwargs)
           ^^^^^^^^^^^^^^^^^^^^^^^^^^^^^^^^^^^^^^
  File "C:\Users\Max\PycharmProjects\News_01\venv\Lib\site-packages\django\views\generic\edit.py", line 153, in post
    return self.form_valid(form)
           ^^^^^^^^^^^^^^^^^^^^^
  File "C:\Users\Max\PycharmProjects\News_01\project\news_article\views.py", line 156, in form_valid
    return super().form_valid(form)
           ^^^^^^^^^^^^^^^^^^^^^^^^
  File "C:\Users\Max\PycharmProjects\News_01\venv\Lib\site-packages\django\views\generic\edit.py", line 135, in form_valid
    self.object = form.save()
                  ^^^^^^^^^^^
  File "C:\Users\Max\PycharmProjects\News_01\venv\Lib\site-packages\django\forms\models.py", line 542, in save
    self.instance.save()
  File "C:\Users\Max\PycharmProjects\News_01\project\news_article\models.py", line 74, in save
    raise ValidationError("Пользователь уже опубликовал максимальное количество записей за сутки.")
django.core.exceptions.ValidationError: ['Пользователь уже опубликовал максимальное количество записей за сутки.']
2023-10-27 15:32:55,954 [ERROR] [basehttp] - "POST /news/create HTTP/1.1" 500 145
2023-10-27 15:38:43,950 [ERROR] [log] - Internal Server Error: /news/articles/create
Traceback (most recent call last):
  File "C:\Users\Max\PycharmProjects\News_01\venv\Lib\site-packages\redis\connection.py", line 707, in connect
    sock = self.retry.call_with_retry(
           ^^^^^^^^^^^^^^^^^^^^^^^^^^^
  File "C:\Users\Max\PycharmProjects\News_01\venv\Lib\site-packages\redis\retry.py", line 46, in call_with_retry
    return do()
           ^^^^
  File "C:\Users\Max\PycharmProjects\News_01\venv\Lib\site-packages\redis\connection.py", line 708, in <lambda>
    lambda: self._connect(), lambda error: self.disconnect(error)
            ^^^^^^^^^^^^^^^
  File "C:\Users\Max\PycharmProjects\News_01\venv\Lib\site-packages\redis\connection.py", line 1006, in _connect
    raise err
  File "C:\Users\Max\PycharmProjects\News_01\venv\Lib\site-packages\redis\connection.py", line 994, in _connect
    sock.connect(socket_address)
ConnectionRefusedError: [WinError 10061] Подключение не установлено, т.к. конечный компьютер отверг запрос на подключение

During handling of the above exception, another exception occurred:

Traceback (most recent call last):
  File "C:\Users\Max\PycharmProjects\News_01\venv\Lib\site-packages\celery\backends\redis.py", line 127, in reconnect_on_error
    yield
  File "C:\Users\Max\PycharmProjects\News_01\venv\Lib\site-packages\celery\backends\redis.py", line 177, in _consume_from
    self._pubsub.subscribe(key)
  File "C:\Users\Max\PycharmProjects\News_01\venv\Lib\site-packages\redis\client.py", line 1634, in subscribe
    ret_val = self.execute_command("SUBSCRIBE", *new_channels.keys())
              ^^^^^^^^^^^^^^^^^^^^^^^^^^^^^^^^^^^^^^^^^^^^^^^^^^^^^^^
  File "C:\Users\Max\PycharmProjects\News_01\venv\Lib\site-packages\redis\client.py", line 1469, in execute_command
    self.connection = self.connection_pool.get_connection(
                      ^^^^^^^^^^^^^^^^^^^^^^^^^^^^^^^^^^^^
  File "C:\Users\Max\PycharmProjects\News_01\venv\Lib\site-packages\redis\connection.py", line 1461, in get_connection
    connection.connect()
  File "C:\Users\Max\PycharmProjects\News_01\venv\Lib\site-packages\redis\connection.py", line 713, in connect
    raise ConnectionError(self._error_message(e))
redis.exceptions.ConnectionError: Error 10061 connecting to 127.0.0.1:6379. Подключение не установлено, т.к. конечный компьютер отверг запрос на подключение.

During handling of the above exception, another exception occurred:

Traceback (most recent call last):
  File "C:\Users\Max\PycharmProjects\News_01\venv\Lib\site-packages\redis\connection.py", line 707, in connect
    sock = self.retry.call_with_retry(
           ^^^^^^^^^^^^^^^^^^^^^^^^^^^
  File "C:\Users\Max\PycharmProjects\News_01\venv\Lib\site-packages\redis\retry.py", line 46, in call_with_retry
    return do()
           ^^^^
  File "C:\Users\Max\PycharmProjects\News_01\venv\Lib\site-packages\redis\connection.py", line 708, in <lambda>
    lambda: self._connect(), lambda error: self.disconnect(error)
            ^^^^^^^^^^^^^^^
  File "C:\Users\Max\PycharmProjects\News_01\venv\Lib\site-packages\redis\connection.py", line 1006, in _connect
    raise err
  File "C:\Users\Max\PycharmProjects\News_01\venv\Lib\site-packages\redis\connection.py", line 994, in _connect
    sock.connect(socket_address)
ConnectionRefusedError: [WinError 10061] Подключение не установлено, т.к. конечный компьютер отверг запрос на подключение

During handling of the above exception, another exception occurred:

Traceback (most recent call last):
  File "C:\Users\Max\PycharmProjects\News_01\venv\Lib\site-packages\kombu\connection.py", line 472, in _reraise_as_library_errors
    yield
  File "C:\Users\Max\PycharmProjects\News_01\venv\Lib\site-packages\celery\app\base.py", line 797, in send_task
    self.backend.on_task_call(P, task_id)
  File "C:\Users\Max\PycharmProjects\News_01\venv\Lib\site-packages\celery\backends\redis.py", line 373, in on_task_call
    self.result_consumer.consume_from(task_id)
  File "C:\Users\Max\PycharmProjects\News_01\venv\Lib\site-packages\celery\backends\redis.py", line 169, in consume_from
    return self.start(task_id)
           ^^^^^^^^^^^^^^^^^^^
  File "C:\Users\Max\PycharmProjects\News_01\venv\Lib\site-packages\celery\backends\redis.py", line 147, in start
    self._consume_from(initial_task_id)
  File "C:\Users\Max\PycharmProjects\News_01\venv\Lib\site-packages\celery\backends\redis.py", line 176, in _consume_from
    with self.reconnect_on_error():
  File "C:\Users\Max\AppData\Local\Programs\Python\Python311\Lib\contextlib.py", line 155, in __exit__
    self.gen.throw(typ, value, traceback)
  File "C:\Users\Max\PycharmProjects\News_01\venv\Lib\site-packages\celery\backends\redis.py", line 130, in reconnect_on_error
    self._ensure(self._reconnect_pubsub, ())
  File "C:\Users\Max\PycharmProjects\News_01\venv\Lib\site-packages\celery\backends\redis.py", line 384, in ensure
    return retry_over_time(
           ^^^^^^^^^^^^^^^^
  File "C:\Users\Max\PycharmProjects\News_01\venv\Lib\site-packages\kombu\utils\functional.py", line 318, in retry_over_time
    return fun(*args, **kwargs)
           ^^^^^^^^^^^^^^^^^^^^
  File "C:\Users\Max\PycharmProjects\News_01\venv\Lib\site-packages\celery\backends\redis.py", line 106, in _reconnect_pubsub
    metas = self.backend.client.mget(self.subscribed_to)
            ^^^^^^^^^^^^^^^^^^^^^^^^^^^^^^^^^^^^^^^^^^^^
  File "C:\Users\Max\PycharmProjects\News_01\venv\Lib\site-packages\redis\commands\core.py", line 2002, in mget
    return self.execute_command("MGET", *args, **options)
           ^^^^^^^^^^^^^^^^^^^^^^^^^^^^^^^^^^^^^^^^^^^^^^
  File "C:\Users\Max\PycharmProjects\News_01\venv\Lib\site-packages\redis\client.py", line 1266, in execute_command
    conn = self.connection or pool.get_connection(command_name, **options)
                              ^^^^^^^^^^^^^^^^^^^^^^^^^^^^^^^^^^^^^^^^^^^^
  File "C:\Users\Max\PycharmProjects\News_01\venv\Lib\site-packages\redis\connection.py", line 1461, in get_connection
    connection.connect()
  File "C:\Users\Max\PycharmProjects\News_01\venv\Lib\site-packages\redis\connection.py", line 713, in connect
    raise ConnectionError(self._error_message(e))
redis.exceptions.ConnectionError: Error 10061 connecting to 127.0.0.1:6379. Подключение не установлено, т.к. конечный компьютер отверг запрос на подключение.

The above exception was the direct cause of the following exception:

Traceback (most recent call last):
  File "C:\Users\Max\PycharmProjects\News_01\venv\Lib\site-packages\django\core\handlers\exception.py", line 55, in inner
    response = get_response(request)
               ^^^^^^^^^^^^^^^^^^^^^
  File "C:\Users\Max\PycharmProjects\News_01\venv\Lib\site-packages\django\core\handlers\base.py", line 197, in _get_response
    response = wrapped_callback(request, *callback_args, **callback_kwargs)
               ^^^^^^^^^^^^^^^^^^^^^^^^^^^^^^^^^^^^^^^^^^^^^^^^^^^^^^^^^^^^
  File "C:\Users\Max\PycharmProjects\News_01\venv\Lib\site-packages\django\views\generic\base.py", line 104, in view
    return self.dispatch(request, *args, **kwargs)
           ^^^^^^^^^^^^^^^^^^^^^^^^^^^^^^^^^^^^^^^
  File "C:\Users\Max\PycharmProjects\News_01\venv\Lib\site-packages\django\contrib\auth\mixins.py", line 109, in dispatch
    return super().dispatch(request, *args, **kwargs)
           ^^^^^^^^^^^^^^^^^^^^^^^^^^^^^^^^^^^^^^^^^^
  File "C:\Users\Max\PycharmProjects\News_01\venv\Lib\site-packages\django\views\generic\base.py", line 143, in dispatch
    return handler(request, *args, **kwargs)
           ^^^^^^^^^^^^^^^^^^^^^^^^^^^^^^^^^
  File "C:\Users\Max\PycharmProjects\News_01\venv\Lib\site-packages\django\views\generic\edit.py", line 184, in post
    return super().post(request, *args, **kwargs)
           ^^^^^^^^^^^^^^^^^^^^^^^^^^^^^^^^^^^^^^
  File "C:\Users\Max\PycharmProjects\News_01\venv\Lib\site-packages\django\views\generic\edit.py", line 153, in post
    return self.form_valid(form)
           ^^^^^^^^^^^^^^^^^^^^^
  File "C:\Users\Max\PycharmProjects\News_01\project\news_article\views.py", line 184, in form_valid
    return super().form_valid(form)
           ^^^^^^^^^^^^^^^^^^^^^^^^
  File "C:\Users\Max\PycharmProjects\News_01\venv\Lib\site-packages\django\views\generic\edit.py", line 135, in form_valid
    self.object = form.save()
                  ^^^^^^^^^^^
  File "C:\Users\Max\PycharmProjects\News_01\venv\Lib\site-packages\django\forms\models.py", line 542, in save
    self.instance.save()
  File "C:\Users\Max\PycharmProjects\News_01\project\news_article\models.py", line 76, in save
    super(Post, self).save(*args, **kwargs)
  File "C:\Users\Max\PycharmProjects\News_01\venv\Lib\site-packages\django\db\models\base.py", line 814, in save
    self.save_base(
  File "C:\Users\Max\PycharmProjects\News_01\venv\Lib\site-packages\django\db\models\base.py", line 892, in save_base
    post_save.send(
  File "C:\Users\Max\PycharmProjects\News_01\venv\Lib\site-packages\django\dispatch\dispatcher.py", line 176, in send
    return [
           ^
  File "C:\Users\Max\PycharmProjects\News_01\venv\Lib\site-packages\django\dispatch\dispatcher.py", line 177, in <listcomp>
    (receiver, receiver(signal=self, sender=sender, **named))
               ^^^^^^^^^^^^^^^^^^^^^^^^^^^^^^^^^^^^^^^^^^^^^
  File "C:\Users\Max\PycharmProjects\News_01\project\news_article\signals.py", line 32, in notify_about_new_post
    send_notifications.delay(instance.text_post, instance.pk, instance.title_post, subscribers_email)
  File "C:\Users\Max\PycharmProjects\News_01\venv\Lib\site-packages\celery\app\task.py", line 444, in delay
    return self.apply_async(args, kwargs)
           ^^^^^^^^^^^^^^^^^^^^^^^^^^^^^^
  File "C:\Users\Max\PycharmProjects\News_01\venv\Lib\site-packages\celery\app\task.py", line 594, in apply_async
    return app.send_task(
           ^^^^^^^^^^^^^^
  File "C:\Users\Max\PycharmProjects\News_01\venv\Lib\site-packages\celery\app\base.py", line 795, in send_task
    with P.connection._reraise_as_library_errors():
  File "C:\Users\Max\AppData\Local\Programs\Python\Python311\Lib\contextlib.py", line 155, in __exit__
    self.gen.throw(typ, value, traceback)
  File "C:\Users\Max\PycharmProjects\News_01\venv\Lib\site-packages\kombu\connection.py", line 476, in _reraise_as_library_errors
    raise ConnectionError(str(exc)) from exc
kombu.exceptions.OperationalError: Error 10061 connecting to 127.0.0.1:6379. Подключение не установлено, т.к. конечный компьютер отверг запрос на подключение.
2023-10-27 15:38:43,961 [ERROR] [basehttp] - "POST /news/articles/create HTTP/1.1" 500 323212
2023-10-27 15:40:19,726 [ERROR] [log] - Internal Server Error: /news/articles/create
Traceback (most recent call last):
  File "C:\Users\Max\PycharmProjects\News_01\venv\Lib\site-packages\redis\connection.py", line 707, in connect
    sock = self.retry.call_with_retry(
           ^^^^^^^^^^^^^^^^^^^^^^^^^^^
  File "C:\Users\Max\PycharmProjects\News_01\venv\Lib\site-packages\redis\retry.py", line 46, in call_with_retry
    return do()
           ^^^^
  File "C:\Users\Max\PycharmProjects\News_01\venv\Lib\site-packages\redis\connection.py", line 708, in <lambda>
    lambda: self._connect(), lambda error: self.disconnect(error)
            ^^^^^^^^^^^^^^^
  File "C:\Users\Max\PycharmProjects\News_01\venv\Lib\site-packages\redis\connection.py", line 1006, in _connect
    raise err
  File "C:\Users\Max\PycharmProjects\News_01\venv\Lib\site-packages\redis\connection.py", line 994, in _connect
    sock.connect(socket_address)
ConnectionRefusedError: [WinError 10061] Подключение не установлено, т.к. конечный компьютер отверг запрос на подключение

During handling of the above exception, another exception occurred:

Traceback (most recent call last):
  File "C:\Users\Max\PycharmProjects\News_01\venv\Lib\site-packages\celery\backends\redis.py", line 127, in reconnect_on_error
    yield
  File "C:\Users\Max\PycharmProjects\News_01\venv\Lib\site-packages\celery\backends\redis.py", line 177, in _consume_from
    self._pubsub.subscribe(key)
  File "C:\Users\Max\PycharmProjects\News_01\venv\Lib\site-packages\redis\client.py", line 1634, in subscribe
    ret_val = self.execute_command("SUBSCRIBE", *new_channels.keys())
              ^^^^^^^^^^^^^^^^^^^^^^^^^^^^^^^^^^^^^^^^^^^^^^^^^^^^^^^
  File "C:\Users\Max\PycharmProjects\News_01\venv\Lib\site-packages\redis\client.py", line 1469, in execute_command
    self.connection = self.connection_pool.get_connection(
                      ^^^^^^^^^^^^^^^^^^^^^^^^^^^^^^^^^^^^
  File "C:\Users\Max\PycharmProjects\News_01\venv\Lib\site-packages\redis\connection.py", line 1461, in get_connection
    connection.connect()
  File "C:\Users\Max\PycharmProjects\News_01\venv\Lib\site-packages\redis\connection.py", line 713, in connect
    raise ConnectionError(self._error_message(e))
redis.exceptions.ConnectionError: Error 10061 connecting to 127.0.0.1:6379. Подключение не установлено, т.к. конечный компьютер отверг запрос на подключение.

During handling of the above exception, another exception occurred:

Traceback (most recent call last):
  File "C:\Users\Max\PycharmProjects\News_01\venv\Lib\site-packages\redis\connection.py", line 707, in connect
    sock = self.retry.call_with_retry(
           ^^^^^^^^^^^^^^^^^^^^^^^^^^^
  File "C:\Users\Max\PycharmProjects\News_01\venv\Lib\site-packages\redis\retry.py", line 46, in call_with_retry
    return do()
           ^^^^
  File "C:\Users\Max\PycharmProjects\News_01\venv\Lib\site-packages\redis\connection.py", line 708, in <lambda>
    lambda: self._connect(), lambda error: self.disconnect(error)
            ^^^^^^^^^^^^^^^
  File "C:\Users\Max\PycharmProjects\News_01\venv\Lib\site-packages\redis\connection.py", line 1006, in _connect
    raise err
  File "C:\Users\Max\PycharmProjects\News_01\venv\Lib\site-packages\redis\connection.py", line 994, in _connect
    sock.connect(socket_address)
ConnectionRefusedError: [WinError 10061] Подключение не установлено, т.к. конечный компьютер отверг запрос на подключение

During handling of the above exception, another exception occurred:

Traceback (most recent call last):
  File "C:\Users\Max\PycharmProjects\News_01\venv\Lib\site-packages\kombu\connection.py", line 472, in _reraise_as_library_errors
    yield
  File "C:\Users\Max\PycharmProjects\News_01\venv\Lib\site-packages\celery\app\base.py", line 797, in send_task
    self.backend.on_task_call(P, task_id)
  File "C:\Users\Max\PycharmProjects\News_01\venv\Lib\site-packages\celery\backends\redis.py", line 373, in on_task_call
    self.result_consumer.consume_from(task_id)
  File "C:\Users\Max\PycharmProjects\News_01\venv\Lib\site-packages\celery\backends\redis.py", line 169, in consume_from
    return self.start(task_id)
           ^^^^^^^^^^^^^^^^^^^
  File "C:\Users\Max\PycharmProjects\News_01\venv\Lib\site-packages\celery\backends\redis.py", line 147, in start
    self._consume_from(initial_task_id)
  File "C:\Users\Max\PycharmProjects\News_01\venv\Lib\site-packages\celery\backends\redis.py", line 176, in _consume_from
    with self.reconnect_on_error():
  File "C:\Users\Max\AppData\Local\Programs\Python\Python311\Lib\contextlib.py", line 155, in __exit__
    self.gen.throw(typ, value, traceback)
  File "C:\Users\Max\PycharmProjects\News_01\venv\Lib\site-packages\celery\backends\redis.py", line 130, in reconnect_on_error
    self._ensure(self._reconnect_pubsub, ())
  File "C:\Users\Max\PycharmProjects\News_01\venv\Lib\site-packages\celery\backends\redis.py", line 384, in ensure
    return retry_over_time(
           ^^^^^^^^^^^^^^^^
  File "C:\Users\Max\PycharmProjects\News_01\venv\Lib\site-packages\kombu\utils\functional.py", line 318, in retry_over_time
    return fun(*args, **kwargs)
           ^^^^^^^^^^^^^^^^^^^^
  File "C:\Users\Max\PycharmProjects\News_01\venv\Lib\site-packages\celery\backends\redis.py", line 106, in _reconnect_pubsub
    metas = self.backend.client.mget(self.subscribed_to)
            ^^^^^^^^^^^^^^^^^^^^^^^^^^^^^^^^^^^^^^^^^^^^
  File "C:\Users\Max\PycharmProjects\News_01\venv\Lib\site-packages\redis\commands\core.py", line 2002, in mget
    return self.execute_command("MGET", *args, **options)
           ^^^^^^^^^^^^^^^^^^^^^^^^^^^^^^^^^^^^^^^^^^^^^^
  File "C:\Users\Max\PycharmProjects\News_01\venv\Lib\site-packages\redis\client.py", line 1266, in execute_command
    conn = self.connection or pool.get_connection(command_name, **options)
                              ^^^^^^^^^^^^^^^^^^^^^^^^^^^^^^^^^^^^^^^^^^^^
  File "C:\Users\Max\PycharmProjects\News_01\venv\Lib\site-packages\redis\connection.py", line 1461, in get_connection
    connection.connect()
  File "C:\Users\Max\PycharmProjects\News_01\venv\Lib\site-packages\redis\connection.py", line 713, in connect
    raise ConnectionError(self._error_message(e))
redis.exceptions.ConnectionError: Error 10061 connecting to 127.0.0.1:6379. Подключение не установлено, т.к. конечный компьютер отверг запрос на подключение.

The above exception was the direct cause of the following exception:

Traceback (most recent call last):
  File "C:\Users\Max\PycharmProjects\News_01\venv\Lib\site-packages\django\core\handlers\exception.py", line 55, in inner
    response = get_response(request)
               ^^^^^^^^^^^^^^^^^^^^^
  File "C:\Users\Max\PycharmProjects\News_01\venv\Lib\site-packages\django\core\handlers\base.py", line 197, in _get_response
    response = wrapped_callback(request, *callback_args, **callback_kwargs)
               ^^^^^^^^^^^^^^^^^^^^^^^^^^^^^^^^^^^^^^^^^^^^^^^^^^^^^^^^^^^^
  File "C:\Users\Max\PycharmProjects\News_01\venv\Lib\site-packages\django\views\generic\base.py", line 104, in view
    return self.dispatch(request, *args, **kwargs)
           ^^^^^^^^^^^^^^^^^^^^^^^^^^^^^^^^^^^^^^^
  File "C:\Users\Max\PycharmProjects\News_01\venv\Lib\site-packages\django\contrib\auth\mixins.py", line 109, in dispatch
    return super().dispatch(request, *args, **kwargs)
           ^^^^^^^^^^^^^^^^^^^^^^^^^^^^^^^^^^^^^^^^^^
  File "C:\Users\Max\PycharmProjects\News_01\venv\Lib\site-packages\django\views\generic\base.py", line 143, in dispatch
    return handler(request, *args, **kwargs)
           ^^^^^^^^^^^^^^^^^^^^^^^^^^^^^^^^^
  File "C:\Users\Max\PycharmProjects\News_01\venv\Lib\site-packages\django\views\generic\edit.py", line 184, in post
    return super().post(request, *args, **kwargs)
           ^^^^^^^^^^^^^^^^^^^^^^^^^^^^^^^^^^^^^^
  File "C:\Users\Max\PycharmProjects\News_01\venv\Lib\site-packages\django\views\generic\edit.py", line 153, in post
    return self.form_valid(form)
           ^^^^^^^^^^^^^^^^^^^^^
  File "C:\Users\Max\PycharmProjects\News_01\project\news_article\views.py", line 184, in form_valid
    return super().form_valid(form)
           ^^^^^^^^^^^^^^^^^^^^^^^^
  File "C:\Users\Max\PycharmProjects\News_01\venv\Lib\site-packages\django\views\generic\edit.py", line 135, in form_valid
    self.object = form.save()
                  ^^^^^^^^^^^
  File "C:\Users\Max\PycharmProjects\News_01\venv\Lib\site-packages\django\forms\models.py", line 542, in save
    self.instance.save()
  File "C:\Users\Max\PycharmProjects\News_01\project\news_article\models.py", line 76, in save
    super(Post, self).save(*args, **kwargs)
  File "C:\Users\Max\PycharmProjects\News_01\venv\Lib\site-packages\django\db\models\base.py", line 814, in save
    self.save_base(
  File "C:\Users\Max\PycharmProjects\News_01\venv\Lib\site-packages\django\db\models\base.py", line 892, in save_base
    post_save.send(
  File "C:\Users\Max\PycharmProjects\News_01\venv\Lib\site-packages\django\dispatch\dispatcher.py", line 176, in send
    return [
           ^
  File "C:\Users\Max\PycharmProjects\News_01\venv\Lib\site-packages\django\dispatch\dispatcher.py", line 177, in <listcomp>
    (receiver, receiver(signal=self, sender=sender, **named))
               ^^^^^^^^^^^^^^^^^^^^^^^^^^^^^^^^^^^^^^^^^^^^^
  File "C:\Users\Max\PycharmProjects\News_01\project\news_article\signals.py", line 32, in notify_about_new_post
    send_notifications.delay(instance.text_post, instance.pk, instance.title_post, subscribers_email)
  File "C:\Users\Max\PycharmProjects\News_01\venv\Lib\site-packages\celery\app\task.py", line 444, in delay
    return self.apply_async(args, kwargs)
           ^^^^^^^^^^^^^^^^^^^^^^^^^^^^^^
  File "C:\Users\Max\PycharmProjects\News_01\venv\Lib\site-packages\celery\app\task.py", line 594, in apply_async
    return app.send_task(
           ^^^^^^^^^^^^^^
  File "C:\Users\Max\PycharmProjects\News_01\venv\Lib\site-packages\celery\app\base.py", line 795, in send_task
    with P.connection._reraise_as_library_errors():
  File "C:\Users\Max\AppData\Local\Programs\Python\Python311\Lib\contextlib.py", line 155, in __exit__
    self.gen.throw(typ, value, traceback)
  File "C:\Users\Max\PycharmProjects\News_01\venv\Lib\site-packages\kombu\connection.py", line 476, in _reraise_as_library_errors
    raise ConnectionError(str(exc)) from exc
kombu.exceptions.OperationalError: Error 10061 connecting to 127.0.0.1:6379. Подключение не установлено, т.к. конечный компьютер отверг запрос на подключение.
2023-10-27 16:35:46,535 [ERROR] [django.request] - Internal Server Error: /news/create
Traceback (most recent call last):
  File "C:\Users\Max\PycharmProjects\News_01\venv\Lib\site-packages\django\core\handlers\exception.py", line 55, in inner
    response = get_response(request)
               ^^^^^^^^^^^^^^^^^^^^^
  File "C:\Users\Max\PycharmProjects\News_01\venv\Lib\site-packages\django\core\handlers\base.py", line 197, in _get_response
    response = wrapped_callback(request, *callback_args, **callback_kwargs)
               ^^^^^^^^^^^^^^^^^^^^^^^^^^^^^^^^^^^^^^^^^^^^^^^^^^^^^^^^^^^^
  File "C:\Users\Max\PycharmProjects\News_01\venv\Lib\site-packages\django\views\generic\base.py", line 104, in view
    return self.dispatch(request, *args, **kwargs)
           ^^^^^^^^^^^^^^^^^^^^^^^^^^^^^^^^^^^^^^^
  File "C:\Users\Max\PycharmProjects\News_01\venv\Lib\site-packages\django\contrib\auth\mixins.py", line 109, in dispatch
    return super().dispatch(request, *args, **kwargs)
           ^^^^^^^^^^^^^^^^^^^^^^^^^^^^^^^^^^^^^^^^^^
  File "C:\Users\Max\PycharmProjects\News_01\venv\Lib\site-packages\django\views\generic\base.py", line 143, in dispatch
    return handler(request, *args, **kwargs)
           ^^^^^^^^^^^^^^^^^^^^^^^^^^^^^^^^^
  File "C:\Users\Max\PycharmProjects\News_01\venv\Lib\site-packages\django\views\generic\edit.py", line 184, in post
    return super().post(request, *args, **kwargs)
           ^^^^^^^^^^^^^^^^^^^^^^^^^^^^^^^^^^^^^^
  File "C:\Users\Max\PycharmProjects\News_01\venv\Lib\site-packages\django\views\generic\edit.py", line 153, in post
    return self.form_valid(form)
           ^^^^^^^^^^^^^^^^^^^^^
  File "C:\Users\Max\PycharmProjects\News_01\project\news_article\views.py", line 156, in form_valid
    return super().form_valid(form)
           ^^^^^^^^^^^^^^^^^^^^^^^^
  File "C:\Users\Max\PycharmProjects\News_01\venv\Lib\site-packages\django\views\generic\edit.py", line 135, in form_valid
    self.object = form.save()
                  ^^^^^^^^^^^
  File "C:\Users\Max\PycharmProjects\News_01\venv\Lib\site-packages\django\forms\models.py", line 542, in save
    self.instance.save()
  File "C:\Users\Max\PycharmProjects\News_01\project\news_article\models.py", line 74, in save
    raise ValidationError("Пользователь уже опубликовал максимальное количество записей за сутки.")
django.core.exceptions.ValidationError: ['Пользователь уже опубликовал максимальное количество записей за сутки.']
2023-10-27 16:35:46,600 [ERROR] [django.server] - "POST /news/create HTTP/1.1" 500 113308
